Workbook

Sheet 1. Фізична доступність
B2: Розділ | C2: Показник | D2: Оцінювання - ДАТА 1 | E2: Оцінювання - ДАТА 2 | F2: Оцінювання - ДАТА 3 | G2: Поточна динаміка по розділу
B3: 1. Доступ до будівлі ззовні (зовнішнє середовище)
B4: Паркування | C4: Розташування до 50 м до головного входу (до доступного входу) | G4: =IF(D4="","",IF(D4="Так",2,0)) | H4: =IF(E4="","",IF(E4="Так",2,0)) | I4: =IF(F4="","",IF(F4="Так",2,0))
C5: Розмір паркувального місця: - ширина 3,5 м; - довжина 6 м | G5: =IF(D5="","",IF(D5="Так",2,0)) | H5: =IF(E5="","",IF(E5="Так",2,0)) | I5: =IF(F5="","",IF(F5="Так",2,0)) | K5: Так
C6: Таких місць є від 10% від загальної кількості, але не менше одного | G6: =IF(D6="","",IF(D6="Так",2,0)) | H6: =IF(E6="","",IF(E6="Так",2,0)) | I6: =IF(F6="","",IF(F6="Так",2,0)) | K6: Ні
C7: Наявна горизонтальна та вертикальна розмітка | G7: =IF(D7="","",IF(D7="Так",2,0)) | H7: =IF(E7="","",IF(E7="Так",2,0)) | I7: =IF(F7="","",IF(F7="Так",2,0))
B8: Шлях руху ззовні | C8: Ширина входу на прилеглу територію та ширина дверей, хвірток (за наявності) становить не менше ніж 0,9 метра у просвіті | G8: =IF(D8="","",IF(D8="Так",2,0)) | H8: =IF(E8="","",IF(E8="Так",2,0)) | I8: =IF(F8="","",IF(F8="Так",2,0))
C9: Ширина пішохідних доріжок із зустрічним рухом по всій довжині становить не менше ніж 1,8 метра | G9: =IF(D9="","",IF(D9="Так",2,0)) | H9: =IF(E9="","",IF(E9="Так",2,0)) | I9: =IF(F9="","",IF(F9="Так",2,0)) | K9: Столбец1 | L9: =D2 -> Оцінювання - ДАТА 1 | M9: =E2 -> Оцінювання - ДАТА 2 | N9: =F2 -> Оцінювання - ДАТА 3
C10: Покриття пішохідних доріжок, тротуарів та пандусів є рівним, без вибоїн | G10: =IF(D10="","",IF(D10="Так",2,0)) | H10: =IF(E10="","",IF(E10="Так",2,0)) | I10: =IF(F10="","",IF(F10="Так",2,0)) | K10: Виконано | L10: =COUNTIF(G4:G15,2) -> 0 | M10: =COUNTIF(H4:H15,2) -> 0 | N10: =COUNTIF(I4:I15,2) -> 0
C11: Покриття пішохідних доріжок, тротуарів і пандусів не містить насипних або крупноструктурних матеріалів | G11: =IF(D11="","",IF(D11="Так",2,0)) | H11: =IF(E11="","",IF(E11="Так",2,0)) | I11: =IF(F11="","",IF(F11="Так",2,0)) | K11: Частково виконано | L11: =COUNTIF(G4:G15,1) -> 0 | M11: =COUNTIF(H4:H15,1) -> 0 | N11: =COUNTIF(I4:I15,1) -> 0
C12: У місцях перетину пішохідні доріжки розташовані на одному рівні та не мають перешкод | G12: =IF(D12="","",IF(D12="Так",2,0)) | H12: =IF(E12="","",IF(E12="Так",2,0)) | I12: =IF(F12="","",IF(F12="Так",2,0)) | K12: Не виконано | L12: =COUNTIF(G4:G15,0) -> 0 | M12: =COUNTIF(H4:H15,0) -> 0 | N12: =COUNTIF(I4:I15,0) -> 0
C13: У темну пору доби наявне вуличне штучне освітлення шляхів руху | G13: =IF(D13="","",IF(D13="Так",2,0)) | H13: =IF(E13="","",IF(E13="Так",2,0)) | I13: =IF(F13="","",IF(F13="Так",2,0))
C14: На шляхах руху відсутні сходи або, у разі їх наявності, забезпечено альтернативні засоби доступу (пандус, підіймальні платформи, підйомники тощо). | G14: =IF(D14="","",IF(D14="Так",2,0)) | H14: =IF(E14="","",IF(E14="Так",2,0)) | I14: =IF(F14="","",IF(F14="Так",2,0))
C15: Перед небезпечними перешкодами для осіб з порушенням зору, а також паралельно до сходів, перед і після сходового маршу влаштовано попереджувальну тактильну смугу. | G15: =IF(D15="","",IF(D15="Так",2,0)) | H15: =IF(E15="","",IF(E15="Так",2,0)) | I15: =IF(F15="","",IF(F15="Так",2,0))
B16: 2. Вхідна зона та вхід у будівлю
B17: Вхідна група: Далі обрати один з трьох варіантів а) б) чи в) | C17: Простір перед вхідною групою (двері, пандус, сходи) є рівним та без пошкоджень покриття (ям, збитої плитки тощо). | G17: =IF(D17="","",IF(D17="Так",2,0)) | H17: =IF(E17="","",IF(E17="Так",2,0)) | I17: =IF(F17="","",IF(F17="Так",2,0))
C18: Простір перед вхідною групою є рівним та вільним від перешкод і перепадів висот. | G18: =IF(D18="","",IF(D18="Так",2,0)) | H18: =IF(E18="","",IF(E18="Так",2,0)) | I18: =IF(F18="","",IF(F18="Так",2,0))
C19: Перед вхідною групою передбачено вільну горизонтальну площину розміром не менше ніж 1,5 × 1,5 м. | G19: =IF(D19="","",IF(D19="Так",2,0)) | H19: =IF(E19="","",IF(E19="Так",2,0)) | I19: =IF(F19="","",IF(F19="Так",2,0))
B20: а) Якщо вхід в рівень | C20: Відсутні пороги. Якщо вони є – вони нівельовані пологим спуском з кутом нахилу до 4,6 градуса (8%). | G20: =IF(D20="","",IF(D20="Так",2,0)) | H20: =IF(E20="","",IF(E20="Так",2,0)) | I20: =IF(F20="","",IF(F20="Так",2,0))
B21: б) Якщо наявний пандус | C21: Нахил пандусу становить менш ніж 8 % (на 1 метр довжини по горизонтальній площині не більше ніж 8 сантиметрів підйому) | G21: =IF(D21="","",IF(D21="Так",2,0)) | H21: =IF(E21="","",IF(E21="Так",2,0)) | I21: =IF(F21="","",IF(F21="Так",2,0)) | K21: Столбец1 | L21: =$D$2 -> Оцінювання - ДАТА 1 | M21: =$E$2 -> Оцінювання - ДАТА 2 | N21: =$F$2 -> Оцінювання - ДАТА 3
C22: Якщо пандус понад 10 метрів: На пандусі мають бути спеціальні майданчики для відпочинку розміром не менше 1,5 × 1,5 м. Вони розміщуються після кожних 0,8 м підйому, тобто приблизно через кожні 10 метрів довжини пандуса. | G22: =IF(D22="","",IF(D22="Так",2,0)) | H22: =IF(E22="","",IF(E22="Так",2,0)) | I22: =IF(F22="","",IF(F22="Так",2,0)) | K22: Виконано | L22: =COUNTIF(G17:G38,2) -> 0 | M22: =COUNTIF(H17:H38,2) -> 0 | N22: =COUNTIF(I17:I38,2) -> 0
C23: Пандуси та сходи обладнані поручнями з обох боків; поручні розміщені на двох рівнях (0,7 м і 0,9 м) і мають горизонтальне продовження 0,3 м зверху та знизу. | G23: =IF(D23="","",IF(D23="Так",2,0)) | H23: =IF(E23="","",IF(E23="Так",2,0)) | I23: =IF(F23="","",IF(F23="Так",2,0)) | K23: Частково виконано | L23: =COUNTIF(G17:G38,1) -> 0 | M23: =COUNTIF(H17:H38,1) -> 0 | N23: =COUNTIF(I17:I38,1) -> 0
C24: У межах одного сходового маршу всі сходинки однакові за формою, шириною та висотою підйому. | G24: =IF(D24="","",IF(D24="Так",2,0)) | H24: =IF(E24="","",IF(E24="Так",2,0)) | I24: =IF(F24="","",IF(F24="Так",2,0)) | K24: Не виконано | L24: =COUNTIF(G17:G38,0) -> 0 | M24: =COUNTIF(H17:H38,0) -> 0 | N24: =COUNTIF(I17:I38,0) -> 0
C25: Пандус забезпечує не менше 1,2 м вільного простору для пересування. | G25: =IF(D25="","",IF(D25="Так",2,0)) | H25: =IF(E25="","",IF(E25="Так",2,0)) | I25: =IF(F25="","",IF(F25="Так",2,0))
C26: Матеріал пандуса неслизький | G26: =IF(D26="","",IF(D26="Так",2,0)) | H26: =IF(E26="","",IF(E26="Так",2,0)) | I26: =IF(F26="","",IF(F26="Так",2,0))
B27: в) Якщо наявний підйомник | C27: Він справний і людина може ним скористатись. | G27: =IF(D27="","",IF(D27="Так",2,0)) | H27: =IF(E27="","",IF(E27="Так",2,0)) | I27: =IF(F27="","",IF(F27="Так",2,0))
B28: Сходи (оцінюємо тільки у разі, якщо є підйомник або пандус) | C28: Однаковий розмір всіх сходинок | G28: =IF(D28="","",IF(D28="Так",2,0)) | H28: =IF(E28="","",IF(E28="Так",2,0)) | I28: =IF(F28="","",IF(F28="Так",2,0))
C29: Перша та остання сходинки контрастно промарковані по всій ширині: • на вертикальній поверхні — смугою шириною не менше 5 см; • на горизонтальній поверхні — смугою шириною не менше 10 см. | G29: =IF(D29="","",IF(D29="Так",2,0)) | H29: =IF(E29="","",IF(E29="Так",2,0)) | I29: =IF(F29="","",IF(F29="Так",2,0))
C30: Поручні сходів установлюються на двох рівнях: 0,7 м і 0,9 м. | G30: =IF(D30="","",IF(D30="Так",2,0)) | H30: =IF(E30="","",IF(E30="Так",2,0)) | I30: =IF(F30="","",IF(F30="Так",2,0))
B31: Вхід в будівлю | C31: Ширина усіх функціональних дверних отворів становить не менше ніж 0,9 м у просвіті. | G31: =IF(D31="","",IF(D31="Так",2,0)) | H31: =IF(E31="","",IF(E31="Так",2,0)) | I31: =IF(F31="","",IF(F31="Так",2,0))
C32: На вході відсутні перепади висоти підлоги. | G32: =IF(D32="","",IF(D32="Так",2,0)) | H32: =IF(E32="","",IF(E32="Так",2,0)) | I32: =IF(F32="","",IF(F32="Так",2,0))
C33: На вході не використовуються решітки для витирання ніг із отворами понад 1,5 см або з рівнем, що не збігається з рівнем підлоги. | G33: =IF(D33="","",IF(D33="Так",2,0)) | H33: =IF(E33="","",IF(E33="Так",2,0)) | I33: =IF(F33="","",IF(F33="Так",2,0))
C34: Майданчик перед входом, а також пандус, сходи та підіймальні пристрої для осіб з інвалідністю захищені від атмосферних опадів навісом. | G34: =IF(D34="","",IF(D34="Так",2,0)) | H34: =IF(E34="","",IF(E34="Так",2,0)) | I34: =IF(F34="","",IF(F34="Так",2,0))
B35: Вхідні двері | C35: Якщо наявні скляні двері – вони контрастно промарковані на висоті 1,2-1,5 м. | G35: =IF(D35="","",IF(D35="Так",2,0)) | H35: =IF(E35="","",IF(E35="Так",2,0)) | I35: =IF(F35="","",IF(F35="Так",2,0))
C36: Двері облаштовані пристосуванням для фіксації дверних стулок у положенні “відчинено” не менше, ніж на 5 секунд. | G36: =IF(D36="","",IF(D36="Так",2,0)) | H36: =IF(E36="","",IF(E36="Так",2,0)) | I36: =IF(F36="","",IF(F36="Так",2,0))
B37: Тамбури | C37: За наявності тамбуру: Глибина тамбурів становить не менше ніж 1,8 метра, ширина — не менше ніж 2,2 метра | G37: =IF(D37="","",IF(D37="Так",2,0)) | H37: =IF(E37="","",IF(E37="Так",2,0)) | I37: =IF(F37="","",IF(F37="Так",2,0))
B38: Турнікети | C38: Прохід без турнікета, або за наявності турнікета – його ширина проходу у просвіті становить не менше ніж 1 метр | G38: =IF(D38="","",IF(D38="Так",2,0)) | H38: =IF(E38="","",IF(E38="Так",2,0)) | I38: =IF(F38="","",IF(F38="Так",2,0))
B39: 3. Інформація та орієнтування (на вході)
B40: Інформаційна табличка | C40: Зовнішня інформаційна табличка: наявна | G40: =IF(D40="","",IF(D40="Так",2,0)) | H40: =IF(E40="","",IF(E40="Так",2,0)) | I40: =IF(F40="","",IF(F40="Так",2,0))
B41: За умови наявності інформаційної таблички: | C41: Містить інформацію про назву та адресу навчального закладу, режим роботи | G41: =IF(D41="","",IF(D41="Так",2,0)) | H41: =IF(E41="","",IF(E41="Так",2,0)) | I41: =IF(F41="","",IF(F41="Так",2,0))
...

Sheet 2. Доступність навч. матеріалів
B2: Показник | C2: ='1. Фізична доступність'!D2 -> Оцінювання - ДАТА 1 | D2: ='1. Фізична доступність'!E2 -> Оцінювання - ДАТА 2 | E2: ='1. Фізична доступність'!F2 -> Оцінювання - ДАТА 3 | F2: Поточна динаміка
B3: Є підручники у цифровому або адаптованому форматі | F3: =IF(C3="","",IF(C3="Зовсім немає",0,IF(C3="Наявні частково",1,IF(C3="Наявні повною мірою",2,"")))) | G3: =IF(D3="","",IF(D3="Зовсім немає",0,IF(D3="Наявні частково",1,IF(D3="Наявні повною мірою",2,"")))) | H3: =IF(E3="","",IF(E3="Зовсім немає",0,IF(E3="Наявні частково",1,IF(E3="Наявні повною мірою",2,"")))) | K3: Столбец1 | L3: =C2 -> Оцінювання - ДАТА 1 | M3: =D2 -> Оцінювання - ДАТА 2 | N3: =E2 -> Оцінювання - ДАТА 3
B4: Є навчальні матеріали зі шрифтом Брайля / великим шрифтом | F4: =IF(C4="","",IF(C4="Зовсім немає",0,IF(C4="Наявні частково",1,IF(C4="Наявні повною мірою",2,"")))) | G4: =IF(D4="","",IF(D4="Зовсім немає",0,IF(D4="Наявні частково",1,IF(D4="Наявні повною мірою",2,"")))) | H4: =IF(E4="","",IF(E4="Зовсім немає",0,IF(E4="Наявні частково",1,IF(E4="Наявні повною мірою",2,"")))) | I4: Так | J4: Зовсім немає | K4: Виконано | L4: =COUNTIF(F3:F8,2) -> 0 | M4: =COUNTIF(G3:G8,2) -> 0 | N4: =COUNTIF(H3:H8,2) -> 0
B5: Навчальні відео мають субтитри / жестовий переклад | F5: =IF(C5="","",IF(C5="Зовсім немає",0,IF(C5="Наявні частково",1,IF(C5="Наявні повною мірою",2,"")))) | G5: =IF(D5="","",IF(D5="Зовсім немає",0,IF(D5="Наявні частково",1,IF(D5="Наявні повною мірою",2,"")))) | H5: =IF(E5="","",IF(E5="Зовсім немає",0,IF(E5="Наявні частково",1,IF(E5="Наявні повною мірою",2,"")))) | I5: Ні | J5: Наявні частково | K5: Частково виконано | L5: =COUNTIF(F3:F8,1) -> 0 | M5: =COUNTIF(G3:G8,1) -> 0 | N5: =COUNTIF(H3:H8,1) -> 0
B6: Можливе використання зчитувача з екрану (скрінрідерів) | F6: =IF(C6="","",IF(C6="Так",2,0)) | G6: =IF(D6="","",IF(D6="Так",2,0)) | H6: =IF(E6="","",IF(E6="Так",2,0)) | J6: Наявні повною мірою | K6: Не виконано | L6: =COUNTIF(F3:F8,0) -> 0 | M6: =COUNTIF(G3:G8,0) -> 0 | N6: =COUNTIF(H3:H8,0) -> 0
B7: Доступні альтернативні форми завдань і тестування | F7: =IF(C7="","",IF(C7="Зовсім немає",0,IF(C7="Наявні частково",1,IF(C7="Наявні повною мірою",2,"")))) | G7: =IF(D7="","",IF(D7="Зовсім немає",0,IF(D7="Наявні частково",1,IF(D7="Наявні повною мірою",2,"")))) | H7: =IF(E7="","",IF(E7="Зовсім немає",0,IF(E7="Наявні частково",1,IF(E7="Наявні повною мірою",2,""))))
B8: Можливість розробити індивідуальний графік навчання | F8: =IF(C8="","",IF(C8="Так",2,0)) | G8: =IF(D8="","",IF(D8="Так",2,0)) | H8: =IF(E8="","",IF(E8="Так",2,0))

Sheet 3. Інклюзивні методи навчання
B2: Показник | C2: ='1. Фізична доступність'!D2 -> Оцінювання - ДАТА 1 | D2: ='1. Фізична доступність'!E2 -> Оцінювання - ДАТА 2 | E2: ='1. Фізична доступність'!F2 -> Оцінювання - ДАТА 3 | F2: Поточна динаміка
B3: Є індивідуальні навчальні плани для студентів з ООП | F3: =IF(C3="","",IF(C3="Зовсім немає",0,IF(C3="Наявні частково",1,IF(C3="Наявні повною мірою",2,"")))) | G3: =IF(D3="","",IF(D3="Зовсім немає",0,IF(D3="Наявні частково",1,IF(D3="Наявні повною мірою",2,"")))) | H3: =IF(E3="","",IF(E3="Зовсім немає",0,IF(E3="Наявні частково",1,IF(E3="Наявні повною мірою",2,"")))) | K3: Столбец1 | L3: =C2 -> Оцінювання - ДАТА 1 | M3: =D2 -> Оцінювання - ДАТА 2 | N3: =E2 -> Оцінювання - ДАТА 3
B4: Викладачі мають підготовку з інклюзивної освіти | F4: =IF(C4="","",IF(C4="Зовсім немає",0,IF(C4="Наявні частково",1,IF(C4="Наявні повною мірою",2,"")))) | G4: =IF(D4="","",IF(D4="Зовсім немає",0,IF(D4="Наявні частково",1,IF(D4="Наявні повною мірою",2,"")))) | H4: =IF(E4="","",IF(E4="Зовсім немає",0,IF(E4="Наявні частково",1,IF(E4="Наявні повною мірою",2,"")))) | I4: Так | J4: Зовсім немає | K4: Виконано | L4: =COUNTIF(F3:F6,2) -> 0 | M4: =COUNTIF(G3:G6,2) -> 0 | N4: =COUNTIF(H3:H6,2) -> 0
B5: Заклад має асистентів учня/учениці або супровідників | F5: =IF(C5="","",IF(C5="Так",2,0)) | G5: =IF(D5="","",IF(D5="Так",2,0)) | H5: =IF(E5="","",IF(E5="Так",2,0)) | I5: Ні | J5: Наявні частково | K5: Частково виконано | L5: =COUNTIF(F3:F6,1) -> 0 | M5: =COUNTIF(G3:G6,1) -> 0 | N5: =COUNTIF(H3:H6,1) -> 0
B6: Психологічна підтримка доступна за запитом | F6: =IF(C6="","",IF(C6="Так",2,0)) | G6: =IF(D6="","",IF(D6="Так",2,0)) | H6: =IF(E6="","",IF(E6="Так",2,0)) | J6: Наявні повною мірою | K6: Не виконано | L6: =COUNTIF(F3:F6,0) -> 0 | M6: =COUNTIF(G3:G6,0) -> 0 | N6: =COUNTIF(H3:H6,0) -> 0

Sheet 4. Комунікаційна доступність
B2: Показник | C2: ='1. Фізична доступність'!D2 -> Оцінювання - ДАТА 1 | D2: ='1. Фізична доступність'!E2 -> Оцінювання - ДАТА 2 | E2: ='1. Фізична доступність'!F2 -> Оцінювання - ДАТА 3 | F2: Поточна динаміка
B3: Інформація надається з урахуванням індивідуальних потреб осіб з інвалідністю шляхом використання письмового, усного та жестового форматів інформування. | F3: =IF(C3="","",IF(C3="Так, повною мірою",2,IF(C3="Так, частково",1,IF(C3="Ні",0,"")))) | G3: =IF(D3="","",IF(D3="Так, повною мірою",2,IF(D3="Так, частково",1,IF(D3="Ні",0,"")))) | H3: =IF(E3="","",IF(E3="Так, повною мірою",2,IF(E3="Так, частково",1,IF(E3="Ні",0,"")))) | K3: Столбец1 | L3: =C2 -> Оцінювання - ДАТА 1 | M3: =D2 -> Оцінювання - ДАТА 2 | N3: =E2 -> Оцінювання - ДАТА 3
B4: Вебсайт закладу відповідає вимогам WCAG: контент є сприйнятним, зрозумілим і керованим для користувачів з інвалідністю. | F4: =IF(C4="","",IF(C4="Так, повною мірою",2,IF(C4="Так, частково",1,IF(C4="Ні",0,"")))) | G4: =IF(D4="","",IF(D4="Так, повною мірою",2,IF(D4="Так, частково",1,IF(D4="Ні",0,"")))) | H4: =IF(E4="","",IF(E4="Так, повною мірою",2,IF(E4="Так, частково",1,IF(E4="Ні",0,"")))) | I4: Так | J4: Так, повною мірою | K4: Виконано | L4: =COUNTIF(F3:F6,2) -> 0 | M4: =COUNTIF(G3:G6,2) -> 0 | N4: =COUNTIF(H3:H6,2) -> 0
B5: Контент у соціальних мережах подається простою мовою, з альтернативним текстом до зображень і маркованими списками. | F5: =IF(C5="","",IF(C5="Так, повною мірою",2,IF(C5="Так, частково",1,IF(C5="Ні",0,"")))) | G5: =IF(D5="","",IF(D5="Так, повною мірою",2,IF(D5="Так, частково",1,IF(D5="Ні",0,"")))) | H5: =IF(E5="","",IF(E5="Так, повною мірою",2,IF(E5="Так, частково",1,IF(E5="Ні",0,"")))) | I5: Ні | J5: Так, частково | K5: Частково виконано | L5: =COUNTIF(F3:F6,1) -> 0 | M5: =COUNTIF(G3:G6,1) -> 0 | N5: =COUNTIF(H3:H6,1) -> 0
B6: Вивіски й навігація виконані з урахуванням доступності (контраст, Брайль, піктограми). | F6: =IF(C6="","",IF(C6="Так, повною мірою",2,IF(C6="Так, частково",1,IF(C6="Ні",0,"")))) | G6: =IF(D6="","",IF(D6="Так, повною мірою",2,IF(D6="Так, частково",1,IF(D6="Ні",0,"")))) | H6: =IF(E6="","",IF(E6="Так, повною мірою",2,IF(E6="Так, частково",1,IF(E6="Ні",0,"")))) | J6: Ні | K6: Не виконано | L6: =COUNTIF(F3:F6,0) -> 0 | M6: =COUNTIF(G3:G6,0) -> 0 | N6: =COUNTIF(H3:H6,0) -> 0

Sheet 5. Адм. підтримка, політики
B2: Показник | C2: ='1. Фізична доступність'!D2 -> Оцінювання - ДАТА 1 | D2: ='1. Фізична доступність'!E2 -> Оцінювання - ДАТА 2 | E2: ='1. Фізична доступність'!F2 -> Оцінювання - ДАТА 3 | F2: Поточна динаміка
B3: У закладі є політика інклюзії та рівного доступу | F3: =IF(C3="","",IF(C3="Так",2,0)) | G3: =IF(D3="","",IF(D3="Так",2,0)) | H3: =IF(E3="","",IF(E3="Так",2,0)) | K3: Столбец1 | L3: =C2 -> Оцінювання - ДАТА 1 | M3: =D2 -> Оцінювання - ДАТА 2 | N3: =E2 -> Оцінювання - ДАТА 3
B4: Призначено відповідального за інклюзивність / доступність | F4: =IF(C4="","",IF(C4="Так",2,0)) | G4: =IF(D4="","",IF(D4="Так",2,0)) | H4: =IF(E4="","",IF(E4="Так",2,0)) | I4: Так | J4: Зовсім немає | K4: Виконано | L4: =COUNTIF(F3:F9,2) -> 0 | M4: =COUNTIF(G3:G9,2) -> 0 | N4: =COUNTIF(H3:H9,2) -> 0
B5: Заклад співпрацює з фахівцями або ГО, що працюють з людьми з інвалідністю | F5: =IF(C5="","",IF(C5="Так",2,0)) | G5: =IF(D5="","",IF(D5="Так",2,0)) | H5: =IF(E5="","",IF(E5="Так",2,0)) | I5: Ні | J5: Наявні частково | K5: Частково виконано | L5: =COUNTIF(F3:F9,1) -> 0 | M5: =COUNTIF(G3:G9,1) -> 0 | N5: =COUNTIF(H3:H9,1) -> 0
B6: Інклюзивність враховується під час планування бюджету та закупівель. | F6: =IF(C6="","",IF(C6="Так",2,0)) | G6: =IF(D6="","",IF(D6="Так",2,0)) | H6: =IF(E6="","",IF(E6="Так",2,0)) | J6: Наявні повною мірою | K6: Не виконано | L6: =COUNTIF(F3:F9,0) -> 0 | M6: =COUNTIF(G3:G9,0) -> 0 | N6: =COUNTIF(H3:H9,0) -> 0
B7: Розроблено та затверджено план заходів з підвищення доступності. | F7: =IF(C7="","",IF(C7="Так",2,0)) | G7: =IF(D7="","",IF(D7="Так",2,0)) | H7: =IF(E7="","",IF(E7="Так",2,0))
B8: Працівники проходять регулярне навчання з питань інклюзії та взаємодії з людьми з інвалідністю. | F8: =IF(C8="","",IF(C8="Так",2,0)) | G8: =IF(D8="","",IF(D8="Так",2,0)) | H8: =IF(E8="","",IF(E8="Так",2,0))
B9: Регулярно проводиться оцінка рівня доступності закладу. | F9: =IF(C9="","",IF(C9="Так",2,0)) | G9: =IF(D9="","",IF(D9="Так",2,0)) | H9: =IF(E9="","",IF(E9="Так",2,0))

Sheet 6. Соціальна інклюзія
B2: Показник | C2: ='1. Фізична доступність'!D2 -> Оцінювання - ДАТА 1 | D2: ='1. Фізична доступність'!E2 -> Оцінювання - ДАТА 2 | E2: ='1. Фізична доступність'!F2 -> Оцінювання - ДАТА 3 | F2: Поточна динаміка
B3: Проводяться інформаційні або просвітницькі заходи з теми інклюзії, протидії дискримінації та булінгу | F3: =IF(C3="","",IF(C3="Так",2,0)) | G3: =IF(D3="","",IF(D3="Так",2,0)) | H3: =IF(E3="","",IF(E3="Так",2,0)) | K3: Столбец1 | L3: =C2 -> Оцінювання - ДАТА 1 | M3: =D2 -> Оцінювання - ДАТА 2 | N3: =E2 -> Оцінювання - ДАТА 3
B4: Наявний механізм подання звернень і скарг щодо доступності (онлайн / офлайн). | F4: =IF(C4="","",IF(C4="Так",2,0)) | G4: =IF(D4="","",IF(D4="Так",2,0)) | H4: =IF(E4="","",IF(E4="Так",2,0)) | I4: Так | J4: Так, повною мірою | K4: Виконано | L4: =COUNTIF(F3:F7,2) -> 0 | M4: =COUNTIF(G3:G7,2) -> 0 | N4: =COUNTIF(H3:H7,2) -> 0
B5: Зворотний зв’язок від осіб з інвалідністю враховується під час ухвалення рішень щодо доступності закладу. | F5: =IF(C5="","",IF(C5="Так",2,0)) | G5: =IF(D5="","",IF(D5="Так",2,0)) | H5: =IF(E5="","",IF(E5="Так",2,0)) | I5: Ні | J5: Так, частково | K5: Частково виконано | L5: =COUNTIF(F3:F7,1) -> 0 | M5: =COUNTIF(G3:G7,1) -> 0 | N5: =COUNTIF(H3:H7,1) -> 0
B6: Гуртки, секції та події враховують потреби різних категорій студентів/учнів | F6: =IF(C6="","",IF(C6="Так, повною мірою",2,IF(C6="Так, частково",1,IF(C6="Ні",0,"")))) | G6: =IF(D6="","",IF(D6="Так, повною мірою",2,IF(D6="Так, частково",1,IF(D6="Ні",0,"")))) | H6: =IF(E6="","",IF(E6="Так, повною мірою",2,IF(E6="Так, частково",1,IF(E6="Ні",0,"")))) | J6: Ні | K6: Не виконано | L6: =COUNTIF(F3:F7,0) -> 0 | M6: =COUNTIF(G3:G7,0) -> 0 | N6: =COUNTIF(H3:H7,0) -> 0
B7: Екскурсії, поїздки та позакласні заходи адаптуються з урахуванням потреб учнів/студентів та персоналу з інвалідністю: продумані зупинки, доступні простори наявність універсальних вбиралень тощо | F7: =IF(C7="","",IF(C7="Так, повною мірою",2,IF(C7="Так, частково",1,IF(C7="Ні",0,"")))) | G7: =IF(D7="","",IF(D7="Так, повною мірою",2,IF(D7="Так, частково",1,IF(D7="Ні",0,"")))) | H7: =IF(E7="","",IF(E7="Так, повною мірою",2,IF(E7="Так, частково",1,IF(E7="Ні",0,""))))

Sheet Загальний результат
B2: Загальний результат
B6: Столбец1 | C6: ='1. Фізична доступність'!D2 -> Оцінювання - ДАТА 1 | D6: ='1. Фізична доступність'!E2 -> Оцінювання - ДАТА 2 | E6: ='1. Фізична доступність'!F2 -> Оцінювання - ДАТА 3
B7: Виконано | C7: =SUM('1. Фізична доступність'!D91+'2. Доступність навч. матеріалів'!L4+'3. Інклюзивні методи навчання'!L4+'4. Комунікаційна доступність'!L4+'5. Адм. підтримка, політики'!L4+'6. Соціальна інклюзія'!L4) -> 0 | D7: =SUM('1. Фізична доступність'!E91+'2. Доступність навч. матеріалів'!M4+'3. Інклюзивні методи навчання'!M4+'4. Комунікаційна доступність'!M4+'5. Адм. підтримка, політики'!M4+'6. Соціальна інклюзія'!M4) -> 0 | E7: =SUM('1. Фізична доступність'!F91+'2. Доступність навч. матеріалів'!N4+'3. Інклюзивні методи навчання'!N4+'4. Комунікаційна доступність'!N4+'5. Адм. підтримка, політики'!N4+'6. Соціальна інклюзія'!N4) -> 0
B8: Частково виконано | C8: =SUM('1. Фізична доступність'!D92+'2. Доступність навч. матеріалів'!L5+'3. Інклюзивні методи навчання'!L5+'4. Комунікаційна доступність'!L5+'5. Адм. підтримка, політики'!L5+'6. Соціальна інклюзія'!L5) -> 0 | D8: =SUM('1. Фізична доступність'!E92+'2. Доступність навч. матеріалів'!M5+'3. Інклюзивні методи навчання'!M5+'4. Комунікаційна доступність'!M5+'5. Адм. підтримка, політики'!M5+'6. Соціальна інклюзія'!M5) -> 0 | E8: =SUM('1. Фізична доступність'!F92+'2. Доступність навч. матеріалів'!N5+'3. Інклюзивні методи навчання'!N5+'4. Комунікаційна доступність'!N5+'5. Адм. підтримка, політики'!N5+'6. Соціальна інклюзія'!N5) -> 0
B9: Не виконано | C9: =SUM('1. Фізична доступність'!D93+'2. Доступність навч. матеріалів'!L6+'3. Інклюзивні методи навчання'!L6+'4. Комунікаційна доступність'!L6+'5. Адм. підтримка, політики'!L6+'6. Соціальна інклюзія'!L6) -> 0 | D9: =SUM('1. Фізична доступність'!E93+'2. Доступність навч. матеріалів'!M6+'3. Інклюзивні методи навчання'!M6+'4. Комунікаційна доступність'!M6+'5. Адм. підтримка, політики'!M6+'6. Соціальна інклюзія'!M6) -> 0 | E9: =SUM('1. Фізична доступність'!F93+'2. Доступність навч. матеріалів'!N6+'3. Інклюзивні методи навчання'!N6+'4. Комунікаційна доступність'!N6+'5. Адм. підтримка, політики'!N6+'6. Соціальна інклюзія'!N6) -> 0
